[2025-09-20T17:46:54.501+0000] {local_task_job_runner.py:123} INFO - ::group::Pre task execution logs
[2025-09-20T17:46:54.591+0000] {taskinstance.py:2614} INFO - Dependencies all met for dep_context=non-requeueable deps ti=<TaskInstance: bronze_full_load_spaceparts.extract_load_fact_Budget scheduled__2024-01-01T00:00:00+00:00 [queued]>
[2025-09-20T17:46:54.639+0000] {taskinstance.py:2614} INFO - Dependencies all met for dep_context=requeueable deps ti=<TaskInstance: bronze_full_load_spaceparts.extract_load_fact_Budget scheduled__2024-01-01T00:00:00+00:00 [queued]>
[2025-09-20T17:46:54.640+0000] {taskinstance.py:2867} INFO - Starting attempt 1 of 3
[2025-09-20T17:46:54.696+0000] {taskinstance.py:2890} INFO - Executing <Task(PythonOperator): extract_load_fact_Budget> on 2024-01-01 00:00:00+00:00
[2025-09-20T17:46:54.726+0000] {standard_task_runner.py:72} INFO - Started process 180 to run task
[2025-09-20T17:46:54.753+0000] {standard_task_runner.py:104} INFO - Running: ['***', 'tasks', 'run', 'bronze_full_load_spaceparts', 'extract_load_fact_Budget', 'scheduled__2024-01-01T00:00:00+00:00', '--job-id', '22', '--raw', '--subdir', 'DAGS_FOLDER/01_Bronce.py', '--cfg-path', '/tmp/tmpzpxv_snd']
[2025-09-20T17:46:54.771+0000] {standard_task_runner.py:105} INFO - Job 22: Subtask extract_load_fact_Budget
[2025-09-20T17:46:56.336+0000] {task_command.py:467} INFO - Running <TaskInstance: bronze_full_load_spaceparts.extract_load_fact_Budget scheduled__2024-01-01T00:00:00+00:00 [running]> on host c1c330a5988a
[2025-09-20T17:46:57.211+0000] {taskinstance.py:3134} INFO - Exporting env vars: AIRFLOW_CTX_DAG_OWNER='data-team' AIRFLOW_CTX_DAG_ID='bronze_full_load_spaceparts' AIRFLOW_CTX_TASK_ID='extract_load_fact_Budget' AIRFLOW_CTX_EXECUTION_DATE='2024-01-01T00:00:00+00:00' AIRFLOW_CTX_TRY_NUMBER='1' AIRFLOW_CTX_DAG_RUN_ID='scheduled__2024-01-01T00:00:00+00:00'
[2025-09-20T17:46:57.214+0000] {taskinstance.py:732} INFO - ::endgroup::
[2025-09-20T17:46:57.357+0000] {01_Bronce.py:321} INFO - Starting extraction for table: fact.Budget
[2025-09-20T17:47:00.877+0000] {01_Bronce.py:333} INFO - Table fact.Budget has 2,947,811 rows
[2025-09-20T17:47:00.878+0000] {01_Bronce.py:347} INFO - Extracting data from fact.Budget
[2025-09-20T17:47:56.003+0000] {01_Bronce.py:364} INFO - Loading 2947811 rows to bronze_fact_budget
[2025-09-20T17:47:56.403+0000] {01_Bronce.py:297} ERROR - Error loading data to bronze_fact_budget: (psycopg2.errors.SyntaxError) syntax error at or near "%"
LINE 4:                 WHERE table_name = %s
                                           ^

[SQL: 
            SELECT EXISTS (
                SELECT FROM information_schema.tables 
                WHERE table_name = %%s
            )
        ]
(Background on this error at: https://sqlalche.me/e/14/f405)
[2025-09-20T17:47:56.403+0000] {01_Bronce.py:382} ERROR - Error processing table fact.Budget: (psycopg2.errors.SyntaxError) syntax error at or near "%"
LINE 4:                 WHERE table_name = %s
                                           ^

[SQL: 
            SELECT EXISTS (
                SELECT FROM information_schema.tables 
                WHERE table_name = %%s
            )
        ]
(Background on this error at: https://sqlalche.me/e/14/f405)
[2025-09-20T17:47:56.450+0000] {taskinstance.py:3313} ERROR - Task failed with exception
Traceback (most recent call last):
  File "/home/airflow/.local/lib/python3.8/site-packages/sqlalchemy/engine/base.py", line 1910, in _execute_context
    self.dialect.do_execute(
  File "/home/airflow/.local/lib/python3.8/site-packages/sqlalchemy/engine/default.py", line 736, in do_execute
    cursor.execute(statement, parameters)
psycopg2.errors.SyntaxError: syntax error at or near "%"
LINE 4:                 WHERE table_name = %s
                                           ^


The above exception was the direct cause of the following exception:

Traceback (most recent call last):
  File "/home/airflow/.local/lib/python3.8/site-packages/airflow/models/taskinstance.py", line 768, in _execute_task
    result = _execute_callable(context=context, **execute_callable_kwargs)
  File "/home/airflow/.local/lib/python3.8/site-packages/airflow/models/taskinstance.py", line 734, in _execute_callable
    return ExecutionCallableRunner(
  File "/home/airflow/.local/lib/python3.8/site-packages/airflow/utils/operator_helpers.py", line 252, in run
    return self.func(*args, **kwargs)
  File "/home/airflow/.local/lib/python3.8/site-packages/airflow/models/baseoperator.py", line 424, in wrapper
    return func(self, *args, **kwargs)
  File "/home/airflow/.local/lib/python3.8/site-packages/airflow/operators/python.py", line 238, in execute
    return_value = self.execute_callable()
  File "/home/airflow/.local/lib/python3.8/site-packages/airflow/operators/python.py", line 256, in execute_callable
    return runner.run(*self.op_args, **self.op_kwargs)
  File "/home/airflow/.local/lib/python3.8/site-packages/airflow/utils/operator_helpers.py", line 252, in run
    return self.func(*args, **kwargs)
  File "/opt/airflow/dags/01_Bronce.py", line 365, in extract_and_load_table
    records_loaded = loader.load_data(df, bronze_table_name, if_exists='replace')
  File "/opt/airflow/dags/01_Bronce.py", line 282, in load_data
    self.create_table_if_not_exists(table_name, df_clean)
  File "/opt/airflow/dags/01_Bronce.py", line 224, in create_table_if_not_exists
    result = conn.execute(text(table_exists_query), (table_name,))
  File "/home/airflow/.local/lib/python3.8/site-packages/sqlalchemy/engine/base.py", line 1385, in execute
    return meth(self, multiparams, params, _EMPTY_EXECUTION_OPTS)
  File "/home/airflow/.local/lib/python3.8/site-packages/sqlalchemy/sql/elements.py", line 334, in _execute_on_connection
    return connection._execute_clauseelement(
  File "/home/airflow/.local/lib/python3.8/site-packages/sqlalchemy/engine/base.py", line 1577, in _execute_clauseelement
    ret = self._execute_context(
  File "/home/airflow/.local/lib/python3.8/site-packages/sqlalchemy/engine/base.py", line 1953, in _execute_context
    self._handle_dbapi_exception(
  File "/home/airflow/.local/lib/python3.8/site-packages/sqlalchemy/engine/base.py", line 2134, in _handle_dbapi_exception
    util.raise_(
  File "/home/airflow/.local/lib/python3.8/site-packages/sqlalchemy/util/compat.py", line 211, in raise_
    raise exception
  File "/home/airflow/.local/lib/python3.8/site-packages/sqlalchemy/engine/base.py", line 1910, in _execute_context
    self.dialect.do_execute(
  File "/home/airflow/.local/lib/python3.8/site-packages/sqlalchemy/engine/default.py", line 736, in do_execute
    cursor.execute(statement, parameters)
sqlalchemy.exc.ProgrammingError: (psycopg2.errors.SyntaxError) syntax error at or near "%"
LINE 4:                 WHERE table_name = %s
                                           ^

[SQL: 
            SELECT EXISTS (
                SELECT FROM information_schema.tables 
                WHERE table_name = %%s
            )
        ]
(Background on this error at: https://sqlalche.me/e/14/f405)
[2025-09-20T17:47:56.489+0000] {taskinstance.py:1226} INFO - Marking task as UP_FOR_RETRY. dag_id=bronze_full_load_spaceparts, task_id=extract_load_fact_Budget, run_id=scheduled__2024-01-01T00:00:00+00:00, execution_date=20240101T000000, start_date=20250920T174654, end_date=20250920T174756
[2025-09-20T17:47:56.583+0000] {taskinstance.py:341} INFO - ::group::Post task execution logs
[2025-09-20T17:47:56.584+0000] {standard_task_runner.py:124} ERROR - Failed to execute job 22 for task extract_load_fact_Budget ((psycopg2.errors.SyntaxError) syntax error at or near "%"
LINE 4:                 WHERE table_name = %s
                                           ^

[SQL: 
            SELECT EXISTS (
                SELECT FROM information_schema.tables 
                WHERE table_name = %%s
            )
        ]
(Background on this error at: https://sqlalche.me/e/14/f405); 180)
Traceback (most recent call last):
  File "/home/airflow/.local/lib/python3.8/site-packages/sqlalchemy/engine/base.py", line 1910, in _execute_context
    self.dialect.do_execute(
  File "/home/airflow/.local/lib/python3.8/site-packages/sqlalchemy/engine/default.py", line 736, in do_execute
    cursor.execute(statement, parameters)
psycopg2.errors.SyntaxError: syntax error at or near "%"
LINE 4:                 WHERE table_name = %s
                                           ^


The above exception was the direct cause of the following exception:

Traceback (most recent call last):
  File "/home/airflow/.local/lib/python3.8/site-packages/airflow/task/task_runner/standard_task_runner.py", line 117, in _start_by_fork
    ret = args.func(args, dag=self.dag)
  File "/home/airflow/.local/lib/python3.8/site-packages/airflow/cli/cli_config.py", line 49, in command
    return func(*args, **kwargs)
  File "/home/airflow/.local/lib/python3.8/site-packages/airflow/utils/cli.py", line 116, in wrapper
    return f(*args, **kwargs)
  File "/home/airflow/.local/lib/python3.8/site-packages/airflow/cli/commands/task_command.py", line 483, in task_run
    task_return_code = _run_task_by_selected_method(args, _dag, ti)
  File "/home/airflow/.local/lib/python3.8/site-packages/airflow/cli/commands/task_command.py", line 256, in _run_task_by_selected_method
    return _run_raw_task(args, ti)
  File "/home/airflow/.local/lib/python3.8/site-packages/airflow/cli/commands/task_command.py", line 341, in _run_raw_task
    return ti._run_raw_task(
  File "/home/airflow/.local/lib/python3.8/site-packages/airflow/utils/session.py", line 97, in wrapper
    return func(*args, session=session, **kwargs)
  File "/home/airflow/.local/lib/python3.8/site-packages/airflow/models/taskinstance.py", line 3006, in _run_raw_task
    return _run_raw_task(
  File "/home/airflow/.local/lib/python3.8/site-packages/airflow/models/taskinstance.py", line 274, in _run_raw_task
    TaskInstance._execute_task_with_callbacks(
  File "/home/airflow/.local/lib/python3.8/site-packages/airflow/models/taskinstance.py", line 3161, in _execute_task_with_callbacks
    result = self._execute_task(context, task_orig)
  File "/home/airflow/.local/lib/python3.8/site-packages/airflow/models/taskinstance.py", line 3185, in _execute_task
    return _execute_task(self, context, task_orig)
  File "/home/airflow/.local/lib/python3.8/site-packages/airflow/models/taskinstance.py", line 768, in _execute_task
    result = _execute_callable(context=context, **execute_callable_kwargs)
  File "/home/airflow/.local/lib/python3.8/site-packages/airflow/models/taskinstance.py", line 734, in _execute_callable
    return ExecutionCallableRunner(
  File "/home/airflow/.local/lib/python3.8/site-packages/airflow/utils/operator_helpers.py", line 252, in run
    return self.func(*args, **kwargs)
  File "/home/airflow/.local/lib/python3.8/site-packages/airflow/models/baseoperator.py", line 424, in wrapper
    return func(self, *args, **kwargs)
  File "/home/airflow/.local/lib/python3.8/site-packages/airflow/operators/python.py", line 238, in execute
    return_value = self.execute_callable()
  File "/home/airflow/.local/lib/python3.8/site-packages/airflow/operators/python.py", line 256, in execute_callable
    return runner.run(*self.op_args, **self.op_kwargs)
  File "/home/airflow/.local/lib/python3.8/site-packages/airflow/utils/operator_helpers.py", line 252, in run
    return self.func(*args, **kwargs)
  File "/opt/airflow/dags/01_Bronce.py", line 365, in extract_and_load_table
    records_loaded = loader.load_data(df, bronze_table_name, if_exists='replace')
  File "/opt/airflow/dags/01_Bronce.py", line 282, in load_data
    self.create_table_if_not_exists(table_name, df_clean)
  File "/opt/airflow/dags/01_Bronce.py", line 224, in create_table_if_not_exists
    result = conn.execute(text(table_exists_query), (table_name,))
  File "/home/airflow/.local/lib/python3.8/site-packages/sqlalchemy/engine/base.py", line 1385, in execute
    return meth(self, multiparams, params, _EMPTY_EXECUTION_OPTS)
  File "/home/airflow/.local/lib/python3.8/site-packages/sqlalchemy/sql/elements.py", line 334, in _execute_on_connection
    return connection._execute_clauseelement(
  File "/home/airflow/.local/lib/python3.8/site-packages/sqlalchemy/engine/base.py", line 1577, in _execute_clauseelement
    ret = self._execute_context(
  File "/home/airflow/.local/lib/python3.8/site-packages/sqlalchemy/engine/base.py", line 1953, in _execute_context
    self._handle_dbapi_exception(
  File "/home/airflow/.local/lib/python3.8/site-packages/sqlalchemy/engine/base.py", line 2134, in _handle_dbapi_exception
    util.raise_(
  File "/home/airflow/.local/lib/python3.8/site-packages/sqlalchemy/util/compat.py", line 211, in raise_
    raise exception
  File "/home/airflow/.local/lib/python3.8/site-packages/sqlalchemy/engine/base.py", line 1910, in _execute_context
    self.dialect.do_execute(
  File "/home/airflow/.local/lib/python3.8/site-packages/sqlalchemy/engine/default.py", line 736, in do_execute
    cursor.execute(statement, parameters)
sqlalchemy.exc.ProgrammingError: (psycopg2.errors.SyntaxError) syntax error at or near "%"
LINE 4:                 WHERE table_name = %s
                                           ^

[SQL: 
            SELECT EXISTS (
                SELECT FROM information_schema.tables 
                WHERE table_name = %%s
            )
        ]
(Background on this error at: https://sqlalche.me/e/14/f405)
[2025-09-20T17:47:56.647+0000] {local_task_job_runner.py:266} INFO - Task exited with return code 1
[2025-09-20T17:47:56.772+0000] {taskinstance.py:3901} INFO - 0 downstream tasks scheduled from follow-on schedule check
[2025-09-20T17:47:56.777+0000] {local_task_job_runner.py:245} INFO - ::endgroup::
[2025-09-20T18:02:24.388+0000] {local_task_job_runner.py:123} INFO - ::group::Pre task execution logs
[2025-09-20T18:02:24.435+0000] {taskinstance.py:2614} INFO - Dependencies all met for dep_context=non-requeueable deps ti=<TaskInstance: bronze_full_load_spaceparts.extract_load_fact_Budget scheduled__2024-01-01T00:00:00+00:00 [queued]>
[2025-09-20T18:02:24.449+0000] {taskinstance.py:2614} INFO - Dependencies all met for dep_context=requeueable deps ti=<TaskInstance: bronze_full_load_spaceparts.extract_load_fact_Budget scheduled__2024-01-01T00:00:00+00:00 [queued]>
[2025-09-20T18:02:24.449+0000] {taskinstance.py:2867} INFO - Starting attempt 1 of 3
[2025-09-20T18:02:24.465+0000] {taskinstance.py:2890} INFO - Executing <Task(PythonOperator): extract_load_fact_Budget> on 2024-01-01 00:00:00+00:00
[2025-09-20T18:02:24.471+0000] {standard_task_runner.py:72} INFO - Started process 146 to run task
[2025-09-20T18:02:24.477+0000] {standard_task_runner.py:104} INFO - Running: ['***', 'tasks', 'run', 'bronze_full_load_spaceparts', 'extract_load_fact_Budget', 'scheduled__2024-01-01T00:00:00+00:00', '--job-id', '66', '--raw', '--subdir', 'DAGS_FOLDER/01_Bronce.py', '--cfg-path', '/tmp/tmpclt3yiwx']
[2025-09-20T18:02:24.481+0000] {standard_task_runner.py:105} INFO - Job 66: Subtask extract_load_fact_Budget
[2025-09-20T18:02:24.783+0000] {task_command.py:467} INFO - Running <TaskInstance: bronze_full_load_spaceparts.extract_load_fact_Budget scheduled__2024-01-01T00:00:00+00:00 [running]> on host dcfe59692ee1
[2025-09-20T18:02:24.876+0000] {taskinstance.py:3134} INFO - Exporting env vars: AIRFLOW_CTX_DAG_OWNER='data-team' AIRFLOW_CTX_DAG_ID='bronze_full_load_spaceparts' AIRFLOW_CTX_TASK_ID='extract_load_fact_Budget' AIRFLOW_CTX_EXECUTION_DATE='2024-01-01T00:00:00+00:00' AIRFLOW_CTX_TRY_NUMBER='1' AIRFLOW_CTX_DAG_RUN_ID='scheduled__2024-01-01T00:00:00+00:00'
[2025-09-20T18:02:24.877+0000] {taskinstance.py:732} INFO - ::endgroup::
[2025-09-20T18:02:24.888+0000] {01_Bronce.py:326} INFO - Starting extraction for table: fact.Budget
[2025-09-20T18:02:28.129+0000] {01_Bronce.py:338} INFO - Table fact.Budget has 2,947,811 rows
[2025-09-20T18:02:28.130+0000] {01_Bronce.py:352} INFO - Extracting data from fact.Budget
[2025-09-20T18:02:58.241+0000] {01_Bronce.py:369} INFO - Loading 2947811 rows to bronze_fact_budget
[2025-09-20T18:02:58.442+0000] {01_Bronce.py:269} ERROR - Error creating table bronze_fact_budget: (psycopg2.errors.DuplicateColumn) column "load_date" specified more than once

[SQL: 
            CREATE TABLE bronze_fact_budget (
                month BIGINT, total_budget DOUBLE PRECISION, customer_key TEXT, product_key BIGINT, dwcreateddate TIMESTAMP, load_date TIMESTAMP, source_system TEXT, load_date TIMESTAMP DEFAULT CURRENT_TIMESTAMP, source_system VARCHAR(50) DEFAULT 'spaceparts'
            )
        ]
(Background on this error at: https://sqlalche.me/e/14/f405)
[2025-09-20T18:02:58.443+0000] {01_Bronce.py:302} ERROR - Error loading data to bronze_fact_budget: (psycopg2.errors.DuplicateColumn) column "load_date" specified more than once

[SQL: 
            CREATE TABLE bronze_fact_budget (
                month BIGINT, total_budget DOUBLE PRECISION, customer_key TEXT, product_key BIGINT, dwcreateddate TIMESTAMP, load_date TIMESTAMP, source_system TEXT, load_date TIMESTAMP DEFAULT CURRENT_TIMESTAMP, source_system VARCHAR(50) DEFAULT 'spaceparts'
            )
        ]
(Background on this error at: https://sqlalche.me/e/14/f405)
[2025-09-20T18:02:58.443+0000] {01_Bronce.py:387} ERROR - Error processing table fact.Budget: (psycopg2.errors.DuplicateColumn) column "load_date" specified more than once

[SQL: 
            CREATE TABLE bronze_fact_budget (
                month BIGINT, total_budget DOUBLE PRECISION, customer_key TEXT, product_key BIGINT, dwcreateddate TIMESTAMP, load_date TIMESTAMP, source_system TEXT, load_date TIMESTAMP DEFAULT CURRENT_TIMESTAMP, source_system VARCHAR(50) DEFAULT 'spaceparts'
            )
        ]
(Background on this error at: https://sqlalche.me/e/14/f405)
[2025-09-20T18:02:58.479+0000] {taskinstance.py:3313} ERROR - Task failed with exception
Traceback (most recent call last):
  File "/home/airflow/.local/lib/python3.8/site-packages/sqlalchemy/engine/base.py", line 1910, in _execute_context
    self.dialect.do_execute(
  File "/home/airflow/.local/lib/python3.8/site-packages/sqlalchemy/engine/default.py", line 736, in do_execute
    cursor.execute(statement, parameters)
psycopg2.errors.DuplicateColumn: column "load_date" specified more than once


The above exception was the direct cause of the following exception:

Traceback (most recent call last):
  File "/home/airflow/.local/lib/python3.8/site-packages/airflow/models/taskinstance.py", line 768, in _execute_task
    result = _execute_callable(context=context, **execute_callable_kwargs)
  File "/home/airflow/.local/lib/python3.8/site-packages/airflow/models/taskinstance.py", line 734, in _execute_callable
    return ExecutionCallableRunner(
  File "/home/airflow/.local/lib/python3.8/site-packages/airflow/utils/operator_helpers.py", line 252, in run
    return self.func(*args, **kwargs)
  File "/home/airflow/.local/lib/python3.8/site-packages/airflow/models/baseoperator.py", line 424, in wrapper
    return func(self, *args, **kwargs)
  File "/home/airflow/.local/lib/python3.8/site-packages/airflow/operators/python.py", line 238, in execute
    return_value = self.execute_callable()
  File "/home/airflow/.local/lib/python3.8/site-packages/airflow/operators/python.py", line 256, in execute_callable
    return runner.run(*self.op_args, **self.op_kwargs)
  File "/home/airflow/.local/lib/python3.8/site-packages/airflow/utils/operator_helpers.py", line 252, in run
    return self.func(*args, **kwargs)
  File "/opt/airflow/dags/01_Bronce.py", line 370, in extract_and_load_table
    records_loaded = loader.load_data(df, bronze_table_name, if_exists='replace')
  File "/opt/airflow/dags/01_Bronce.py", line 287, in load_data
    self.create_table_if_not_exists(table_name, df_clean)
  File "/opt/airflow/dags/01_Bronce.py", line 265, in create_table_if_not_exists
    conn.execute(text(create_table_sql))
  File "/home/airflow/.local/lib/python3.8/site-packages/sqlalchemy/engine/base.py", line 1385, in execute
    return meth(self, multiparams, params, _EMPTY_EXECUTION_OPTS)
  File "/home/airflow/.local/lib/python3.8/site-packages/sqlalchemy/sql/elements.py", line 334, in _execute_on_connection
    return connection._execute_clauseelement(
  File "/home/airflow/.local/lib/python3.8/site-packages/sqlalchemy/engine/base.py", line 1577, in _execute_clauseelement
    ret = self._execute_context(
  File "/home/airflow/.local/lib/python3.8/site-packages/sqlalchemy/engine/base.py", line 1953, in _execute_context
    self._handle_dbapi_exception(
  File "/home/airflow/.local/lib/python3.8/site-packages/sqlalchemy/engine/base.py", line 2134, in _handle_dbapi_exception
    util.raise_(
  File "/home/airflow/.local/lib/python3.8/site-packages/sqlalchemy/util/compat.py", line 211, in raise_
    raise exception
  File "/home/airflow/.local/lib/python3.8/site-packages/sqlalchemy/engine/base.py", line 1910, in _execute_context
    self.dialect.do_execute(
  File "/home/airflow/.local/lib/python3.8/site-packages/sqlalchemy/engine/default.py", line 736, in do_execute
    cursor.execute(statement, parameters)
sqlalchemy.exc.ProgrammingError: (psycopg2.errors.DuplicateColumn) column "load_date" specified more than once

[SQL: 
            CREATE TABLE bronze_fact_budget (
                month BIGINT, total_budget DOUBLE PRECISION, customer_key TEXT, product_key BIGINT, dwcreateddate TIMESTAMP, load_date TIMESTAMP, source_system TEXT, load_date TIMESTAMP DEFAULT CURRENT_TIMESTAMP, source_system VARCHAR(50) DEFAULT 'spaceparts'
            )
        ]
(Background on this error at: https://sqlalche.me/e/14/f405)
[2025-09-20T18:02:58.501+0000] {taskinstance.py:1226} INFO - Marking task as UP_FOR_RETRY. dag_id=bronze_full_load_spaceparts, task_id=extract_load_fact_Budget, run_id=scheduled__2024-01-01T00:00:00+00:00, execution_date=20240101T000000, start_date=20250920T180224, end_date=20250920T180258
[2025-09-20T18:02:58.537+0000] {taskinstance.py:341} INFO - ::group::Post task execution logs
[2025-09-20T18:02:58.537+0000] {standard_task_runner.py:124} ERROR - Failed to execute job 66 for task extract_load_fact_Budget ((psycopg2.errors.DuplicateColumn) column "load_date" specified more than once

[SQL: 
            CREATE TABLE bronze_fact_budget (
                month BIGINT, total_budget DOUBLE PRECISION, customer_key TEXT, product_key BIGINT, dwcreateddate TIMESTAMP, load_date TIMESTAMP, source_system TEXT, load_date TIMESTAMP DEFAULT CURRENT_TIMESTAMP, source_system VARCHAR(50) DEFAULT 'spaceparts'
            )
        ]
(Background on this error at: https://sqlalche.me/e/14/f405); 146)
Traceback (most recent call last):
  File "/home/airflow/.local/lib/python3.8/site-packages/sqlalchemy/engine/base.py", line 1910, in _execute_context
    self.dialect.do_execute(
  File "/home/airflow/.local/lib/python3.8/site-packages/sqlalchemy/engine/default.py", line 736, in do_execute
    cursor.execute(statement, parameters)
psycopg2.errors.DuplicateColumn: column "load_date" specified more than once


The above exception was the direct cause of the following exception:

Traceback (most recent call last):
  File "/home/airflow/.local/lib/python3.8/site-packages/airflow/task/task_runner/standard_task_runner.py", line 117, in _start_by_fork
    ret = args.func(args, dag=self.dag)
  File "/home/airflow/.local/lib/python3.8/site-packages/airflow/cli/cli_config.py", line 49, in command
    return func(*args, **kwargs)
  File "/home/airflow/.local/lib/python3.8/site-packages/airflow/utils/cli.py", line 116, in wrapper
    return f(*args, **kwargs)
  File "/home/airflow/.local/lib/python3.8/site-packages/airflow/cli/commands/task_command.py", line 483, in task_run
    task_return_code = _run_task_by_selected_method(args, _dag, ti)
  File "/home/airflow/.local/lib/python3.8/site-packages/airflow/cli/commands/task_command.py", line 256, in _run_task_by_selected_method
    return _run_raw_task(args, ti)
  File "/home/airflow/.local/lib/python3.8/site-packages/airflow/cli/commands/task_command.py", line 341, in _run_raw_task
    return ti._run_raw_task(
  File "/home/airflow/.local/lib/python3.8/site-packages/airflow/utils/session.py", line 97, in wrapper
    return func(*args, session=session, **kwargs)
  File "/home/airflow/.local/lib/python3.8/site-packages/airflow/models/taskinstance.py", line 3006, in _run_raw_task
    return _run_raw_task(
  File "/home/airflow/.local/lib/python3.8/site-packages/airflow/models/taskinstance.py", line 274, in _run_raw_task
    TaskInstance._execute_task_with_callbacks(
  File "/home/airflow/.local/lib/python3.8/site-packages/airflow/models/taskinstance.py", line 3161, in _execute_task_with_callbacks
    result = self._execute_task(context, task_orig)
  File "/home/airflow/.local/lib/python3.8/site-packages/airflow/models/taskinstance.py", line 3185, in _execute_task
    return _execute_task(self, context, task_orig)
  File "/home/airflow/.local/lib/python3.8/site-packages/airflow/models/taskinstance.py", line 768, in _execute_task
    result = _execute_callable(context=context, **execute_callable_kwargs)
  File "/home/airflow/.local/lib/python3.8/site-packages/airflow/models/taskinstance.py", line 734, in _execute_callable
    return ExecutionCallableRunner(
  File "/home/airflow/.local/lib/python3.8/site-packages/airflow/utils/operator_helpers.py", line 252, in run
    return self.func(*args, **kwargs)
  File "/home/airflow/.local/lib/python3.8/site-packages/airflow/models/baseoperator.py", line 424, in wrapper
    return func(self, *args, **kwargs)
  File "/home/airflow/.local/lib/python3.8/site-packages/airflow/operators/python.py", line 238, in execute
    return_value = self.execute_callable()
  File "/home/airflow/.local/lib/python3.8/site-packages/airflow/operators/python.py", line 256, in execute_callable
    return runner.run(*self.op_args, **self.op_kwargs)
  File "/home/airflow/.local/lib/python3.8/site-packages/airflow/utils/operator_helpers.py", line 252, in run
    return self.func(*args, **kwargs)
  File "/opt/airflow/dags/01_Bronce.py", line 370, in extract_and_load_table
    records_loaded = loader.load_data(df, bronze_table_name, if_exists='replace')
  File "/opt/airflow/dags/01_Bronce.py", line 287, in load_data
    self.create_table_if_not_exists(table_name, df_clean)
  File "/opt/airflow/dags/01_Bronce.py", line 265, in create_table_if_not_exists
    conn.execute(text(create_table_sql))
  File "/home/airflow/.local/lib/python3.8/site-packages/sqlalchemy/engine/base.py", line 1385, in execute
    return meth(self, multiparams, params, _EMPTY_EXECUTION_OPTS)
  File "/home/airflow/.local/lib/python3.8/site-packages/sqlalchemy/sql/elements.py", line 334, in _execute_on_connection
    return connection._execute_clauseelement(
  File "/home/airflow/.local/lib/python3.8/site-packages/sqlalchemy/engine/base.py", line 1577, in _execute_clauseelement
    ret = self._execute_context(
  File "/home/airflow/.local/lib/python3.8/site-packages/sqlalchemy/engine/base.py", line 1953, in _execute_context
    self._handle_dbapi_exception(
  File "/home/airflow/.local/lib/python3.8/site-packages/sqlalchemy/engine/base.py", line 2134, in _handle_dbapi_exception
    util.raise_(
  File "/home/airflow/.local/lib/python3.8/site-packages/sqlalchemy/util/compat.py", line 211, in raise_
    raise exception
  File "/home/airflow/.local/lib/python3.8/site-packages/sqlalchemy/engine/base.py", line 1910, in _execute_context
    self.dialect.do_execute(
  File "/home/airflow/.local/lib/python3.8/site-packages/sqlalchemy/engine/default.py", line 736, in do_execute
    cursor.execute(statement, parameters)
sqlalchemy.exc.ProgrammingError: (psycopg2.errors.DuplicateColumn) column "load_date" specified more than once

[SQL: 
            CREATE TABLE bronze_fact_budget (
                month BIGINT, total_budget DOUBLE PRECISION, customer_key TEXT, product_key BIGINT, dwcreateddate TIMESTAMP, load_date TIMESTAMP, source_system TEXT, load_date TIMESTAMP DEFAULT CURRENT_TIMESTAMP, source_system VARCHAR(50) DEFAULT 'spaceparts'
            )
        ]
(Background on this error at: https://sqlalche.me/e/14/f405)
[2025-09-20T18:02:58.589+0000] {local_task_job_runner.py:266} INFO - Task exited with return code 1
[2025-09-20T18:02:58.643+0000] {taskinstance.py:3901} INFO - 0 downstream tasks scheduled from follow-on schedule check
[2025-09-20T18:02:58.645+0000] {local_task_job_runner.py:245} INFO - ::endgroup::
[2025-09-20T18:31:45.515+0000] {local_task_job_runner.py:123} INFO - ::group::Pre task execution logs
[2025-09-20T18:31:45.574+0000] {taskinstance.py:2614} INFO - Dependencies all met for dep_context=non-requeueable deps ti=<TaskInstance: bronze_full_load_spaceparts.extract_load_fact_Budget scheduled__2024-01-01T00:00:00+00:00 [queued]>
[2025-09-20T18:31:45.600+0000] {taskinstance.py:2614} INFO - Dependencies all met for dep_context=requeueable deps ti=<TaskInstance: bronze_full_load_spaceparts.extract_load_fact_Budget scheduled__2024-01-01T00:00:00+00:00 [queued]>
[2025-09-20T18:31:45.601+0000] {taskinstance.py:2867} INFO - Starting attempt 1 of 3
[2025-09-20T18:31:45.634+0000] {taskinstance.py:2890} INFO - Executing <Task(PythonOperator): extract_load_fact_Budget> on 2024-01-01 00:00:00+00:00
[2025-09-20T18:31:45.642+0000] {standard_task_runner.py:72} INFO - Started process 179 to run task
[2025-09-20T18:31:45.660+0000] {standard_task_runner.py:104} INFO - Running: ['***', 'tasks', 'run', 'bronze_full_load_spaceparts', 'extract_load_fact_Budget', 'scheduled__2024-01-01T00:00:00+00:00', '--job-id', '111', '--raw', '--subdir', 'DAGS_FOLDER/01_Bronce.py', '--cfg-path', '/tmp/tmp3bbamqcd']
[2025-09-20T18:31:45.668+0000] {standard_task_runner.py:105} INFO - Job 111: Subtask extract_load_fact_Budget
[2025-09-20T18:31:46.256+0000] {task_command.py:467} INFO - Running <TaskInstance: bronze_full_load_spaceparts.extract_load_fact_Budget scheduled__2024-01-01T00:00:00+00:00 [running]> on host 4c4d6e18e259
[2025-09-20T18:31:46.456+0000] {taskinstance.py:3134} INFO - Exporting env vars: AIRFLOW_CTX_DAG_OWNER='data-team' AIRFLOW_CTX_DAG_ID='bronze_full_load_spaceparts' AIRFLOW_CTX_TASK_ID='extract_load_fact_Budget' AIRFLOW_CTX_EXECUTION_DATE='2024-01-01T00:00:00+00:00' AIRFLOW_CTX_TRY_NUMBER='1' AIRFLOW_CTX_DAG_RUN_ID='scheduled__2024-01-01T00:00:00+00:00'
[2025-09-20T18:31:46.458+0000] {taskinstance.py:732} INFO - ::endgroup::
[2025-09-20T18:31:46.483+0000] {01_Bronce.py:279} INFO - Starting extraction for table: fact.Budget
[2025-09-20T18:31:49.652+0000] {01_Bronce.py:291} INFO - Table fact.Budget has 2,947,811 rows
[2025-09-20T18:31:49.652+0000] {01_Bronce.py:305} INFO - Extracting data from fact.Budget
[2025-09-20T18:32:21.392+0000] {01_Bronce.py:322} INFO - Loading 2947811 rows to bronze_fact_budget
[2025-09-20T18:39:19.749+0000] {01_Bronce.py:250} INFO - Loaded 2947811 rows to bronze_fact_budget
[2025-09-20T18:39:20.052+0000] {01_Bronce.py:333} INFO - Successfully loaded 2,947,811 records to bronze_fact_budget
[2025-09-20T18:39:20.160+0000] {python.py:240} INFO - Done. Returned value was: {'source_table': 'fact.Budget', 'bronze_table': 'bronze_fact_budget', 'record_count': 2947811, 'status': 'success', 'extraction_time': '2025-09-20T18:39:20.052303'}
[2025-09-20T18:39:20.188+0000] {taskinstance.py:341} INFO - ::group::Post task execution logs
[2025-09-20T18:39:20.188+0000] {taskinstance.py:353} INFO - Marking task as SUCCESS. dag_id=bronze_full_load_spaceparts, task_id=extract_load_fact_Budget, run_id=scheduled__2024-01-01T00:00:00+00:00, execution_date=20240101T000000, start_date=20250920T183145, end_date=20250920T183920
[2025-09-20T18:39:20.285+0000] {local_task_job_runner.py:266} INFO - Task exited with return code 0
[2025-09-20T18:39:20.463+0000] {taskinstance.py:3901} INFO - 0 downstream tasks scheduled from follow-on schedule check
[2025-09-20T18:39:20.465+0000] {local_task_job_runner.py:245} INFO - ::endgroup::
