[2025-09-20T17:52:57.448+0000] {local_task_job_runner.py:123} INFO - ::group::Pre task execution logs
[2025-09-20T17:52:57.463+0000] {taskinstance.py:2614} INFO - Dependencies all met for dep_context=non-requeueable deps ti=<TaskInstance: bronze_full_load_spaceparts.extract_load_fact_Budget scheduled__2024-01-01T00:00:00+00:00 [queued]>
[2025-09-20T17:52:57.470+0000] {taskinstance.py:2614} INFO - Dependencies all met for dep_context=requeueable deps ti=<TaskInstance: bronze_full_load_spaceparts.extract_load_fact_Budget scheduled__2024-01-01T00:00:00+00:00 [queued]>
[2025-09-20T17:52:57.470+0000] {taskinstance.py:2867} INFO - Starting attempt 2 of 3
[2025-09-20T17:52:57.479+0000] {taskinstance.py:2890} INFO - Executing <Task(PythonOperator): extract_load_fact_Budget> on 2024-01-01 00:00:00+00:00
[2025-09-20T17:52:57.484+0000] {standard_task_runner.py:72} INFO - Started process 150 to run task
[2025-09-20T17:52:57.488+0000] {standard_task_runner.py:104} INFO - Running: ['***', 'tasks', 'run', 'bronze_full_load_spaceparts', 'extract_load_fact_Budget', 'scheduled__2024-01-01T00:00:00+00:00', '--job-id', '43', '--raw', '--subdir', 'DAGS_FOLDER/01_Bronce.py', '--cfg-path', '/tmp/tmp236y5lwa']
[2025-09-20T17:52:57.491+0000] {standard_task_runner.py:105} INFO - Job 43: Subtask extract_load_fact_Budget
[2025-09-20T17:52:57.814+0000] {task_command.py:467} INFO - Running <TaskInstance: bronze_full_load_spaceparts.extract_load_fact_Budget scheduled__2024-01-01T00:00:00+00:00 [running]> on host 2ddf28c2d814
[2025-09-20T17:52:57.878+0000] {taskinstance.py:3134} INFO - Exporting env vars: AIRFLOW_CTX_DAG_OWNER='data-team' AIRFLOW_CTX_DAG_ID='bronze_full_load_spaceparts' AIRFLOW_CTX_TASK_ID='extract_load_fact_Budget' AIRFLOW_CTX_EXECUTION_DATE='2024-01-01T00:00:00+00:00' AIRFLOW_CTX_TRY_NUMBER='2' AIRFLOW_CTX_DAG_RUN_ID='scheduled__2024-01-01T00:00:00+00:00'
[2025-09-20T17:52:57.879+0000] {taskinstance.py:732} INFO - ::endgroup::
[2025-09-20T17:52:57.885+0000] {01_Bronce.py:327} INFO - Starting extraction for table: fact.Budget
[2025-09-20T17:53:01.148+0000] {01_Bronce.py:339} INFO - Table fact.Budget has 2,947,811 rows
[2025-09-20T17:53:01.148+0000] {01_Bronce.py:353} INFO - Extracting data from fact.Budget
[2025-09-20T17:53:25.978+0000] {01_Bronce.py:370} INFO - Loading 2947811 rows to bronze_fact_budget
[2025-09-20T17:53:26.105+0000] {01_Bronce.py:303} ERROR - Error loading data to bronze_fact_budget: (psycopg2.errors.SyntaxError) syntax error at or near "%"
LINE 4:                 WHERE table_name = %s
                                           ^

[SQL: 
            SELECT EXISTS (
                SELECT FROM information_schema.tables 
                WHERE table_name = %%s
            )
        ]
(Background on this error at: https://sqlalche.me/e/14/f405)
[2025-09-20T17:53:26.105+0000] {01_Bronce.py:388} ERROR - Error processing table fact.Budget: (psycopg2.errors.SyntaxError) syntax error at or near "%"
LINE 4:                 WHERE table_name = %s
                                           ^

[SQL: 
            SELECT EXISTS (
                SELECT FROM information_schema.tables 
                WHERE table_name = %%s
            )
        ]
(Background on this error at: https://sqlalche.me/e/14/f405)
[2025-09-20T17:53:26.128+0000] {taskinstance.py:3313} ERROR - Task failed with exception
Traceback (most recent call last):
  File "/home/airflow/.local/lib/python3.8/site-packages/sqlalchemy/engine/base.py", line 1910, in _execute_context
    self.dialect.do_execute(
  File "/home/airflow/.local/lib/python3.8/site-packages/sqlalchemy/engine/default.py", line 736, in do_execute
    cursor.execute(statement, parameters)
psycopg2.errors.SyntaxError: syntax error at or near "%"
LINE 4:                 WHERE table_name = %s
                                           ^


The above exception was the direct cause of the following exception:

Traceback (most recent call last):
  File "/home/airflow/.local/lib/python3.8/site-packages/airflow/models/taskinstance.py", line 768, in _execute_task
    result = _execute_callable(context=context, **execute_callable_kwargs)
  File "/home/airflow/.local/lib/python3.8/site-packages/airflow/models/taskinstance.py", line 734, in _execute_callable
    return ExecutionCallableRunner(
  File "/home/airflow/.local/lib/python3.8/site-packages/airflow/utils/operator_helpers.py", line 252, in run
    return self.func(*args, **kwargs)
  File "/home/airflow/.local/lib/python3.8/site-packages/airflow/models/baseoperator.py", line 424, in wrapper
    return func(self, *args, **kwargs)
  File "/home/airflow/.local/lib/python3.8/site-packages/airflow/operators/python.py", line 238, in execute
    return_value = self.execute_callable()
  File "/home/airflow/.local/lib/python3.8/site-packages/airflow/operators/python.py", line 256, in execute_callable
    return runner.run(*self.op_args, **self.op_kwargs)
  File "/home/airflow/.local/lib/python3.8/site-packages/airflow/utils/operator_helpers.py", line 252, in run
    return self.func(*args, **kwargs)
  File "/opt/airflow/dags/01_Bronce.py", line 371, in extract_and_load_table
    records_loaded = loader.load_data(df, bronze_table_name, if_exists='replace')
  File "/opt/airflow/dags/01_Bronce.py", line 288, in load_data
    self.create_table_if_not_exists(table_name, df_clean)
  File "/opt/airflow/dags/01_Bronce.py", line 230, in create_table_if_not_exists
    result = conn.execute(text(table_exists_query), (table_name,))
  File "/home/airflow/.local/lib/python3.8/site-packages/sqlalchemy/engine/base.py", line 1385, in execute
    return meth(self, multiparams, params, _EMPTY_EXECUTION_OPTS)
  File "/home/airflow/.local/lib/python3.8/site-packages/sqlalchemy/sql/elements.py", line 334, in _execute_on_connection
    return connection._execute_clauseelement(
  File "/home/airflow/.local/lib/python3.8/site-packages/sqlalchemy/engine/base.py", line 1577, in _execute_clauseelement
    ret = self._execute_context(
  File "/home/airflow/.local/lib/python3.8/site-packages/sqlalchemy/engine/base.py", line 1953, in _execute_context
    self._handle_dbapi_exception(
  File "/home/airflow/.local/lib/python3.8/site-packages/sqlalchemy/engine/base.py", line 2134, in _handle_dbapi_exception
    util.raise_(
  File "/home/airflow/.local/lib/python3.8/site-packages/sqlalchemy/util/compat.py", line 211, in raise_
    raise exception
  File "/home/airflow/.local/lib/python3.8/site-packages/sqlalchemy/engine/base.py", line 1910, in _execute_context
    self.dialect.do_execute(
  File "/home/airflow/.local/lib/python3.8/site-packages/sqlalchemy/engine/default.py", line 736, in do_execute
    cursor.execute(statement, parameters)
sqlalchemy.exc.ProgrammingError: (psycopg2.errors.SyntaxError) syntax error at or near "%"
LINE 4:                 WHERE table_name = %s
                                           ^

[SQL: 
            SELECT EXISTS (
                SELECT FROM information_schema.tables 
                WHERE table_name = %%s
            )
        ]
(Background on this error at: https://sqlalche.me/e/14/f405)
[2025-09-20T17:53:26.153+0000] {taskinstance.py:1226} INFO - Marking task as UP_FOR_RETRY. dag_id=bronze_full_load_spaceparts, task_id=extract_load_fact_Budget, run_id=scheduled__2024-01-01T00:00:00+00:00, execution_date=20240101T000000, start_date=20250920T175257, end_date=20250920T175326
[2025-09-20T17:53:26.222+0000] {taskinstance.py:341} INFO - ::group::Post task execution logs
[2025-09-20T17:53:26.222+0000] {standard_task_runner.py:124} ERROR - Failed to execute job 43 for task extract_load_fact_Budget ((psycopg2.errors.SyntaxError) syntax error at or near "%"
LINE 4:                 WHERE table_name = %s
                                           ^

[SQL: 
            SELECT EXISTS (
                SELECT FROM information_schema.tables 
                WHERE table_name = %%s
            )
        ]
(Background on this error at: https://sqlalche.me/e/14/f405); 150)
Traceback (most recent call last):
  File "/home/airflow/.local/lib/python3.8/site-packages/sqlalchemy/engine/base.py", line 1910, in _execute_context
    self.dialect.do_execute(
  File "/home/airflow/.local/lib/python3.8/site-packages/sqlalchemy/engine/default.py", line 736, in do_execute
    cursor.execute(statement, parameters)
psycopg2.errors.SyntaxError: syntax error at or near "%"
LINE 4:                 WHERE table_name = %s
                                           ^


The above exception was the direct cause of the following exception:

Traceback (most recent call last):
  File "/home/airflow/.local/lib/python3.8/site-packages/airflow/task/task_runner/standard_task_runner.py", line 117, in _start_by_fork
    ret = args.func(args, dag=self.dag)
  File "/home/airflow/.local/lib/python3.8/site-packages/airflow/cli/cli_config.py", line 49, in command
    return func(*args, **kwargs)
  File "/home/airflow/.local/lib/python3.8/site-packages/airflow/utils/cli.py", line 116, in wrapper
    return f(*args, **kwargs)
  File "/home/airflow/.local/lib/python3.8/site-packages/airflow/cli/commands/task_command.py", line 483, in task_run
    task_return_code = _run_task_by_selected_method(args, _dag, ti)
  File "/home/airflow/.local/lib/python3.8/site-packages/airflow/cli/commands/task_command.py", line 256, in _run_task_by_selected_method
    return _run_raw_task(args, ti)
  File "/home/airflow/.local/lib/python3.8/site-packages/airflow/cli/commands/task_command.py", line 341, in _run_raw_task
    return ti._run_raw_task(
  File "/home/airflow/.local/lib/python3.8/site-packages/airflow/utils/session.py", line 97, in wrapper
    return func(*args, session=session, **kwargs)
  File "/home/airflow/.local/lib/python3.8/site-packages/airflow/models/taskinstance.py", line 3006, in _run_raw_task
    return _run_raw_task(
  File "/home/airflow/.local/lib/python3.8/site-packages/airflow/models/taskinstance.py", line 274, in _run_raw_task
    TaskInstance._execute_task_with_callbacks(
  File "/home/airflow/.local/lib/python3.8/site-packages/airflow/models/taskinstance.py", line 3161, in _execute_task_with_callbacks
    result = self._execute_task(context, task_orig)
  File "/home/airflow/.local/lib/python3.8/site-packages/airflow/models/taskinstance.py", line 3185, in _execute_task
    return _execute_task(self, context, task_orig)
  File "/home/airflow/.local/lib/python3.8/site-packages/airflow/models/taskinstance.py", line 768, in _execute_task
    result = _execute_callable(context=context, **execute_callable_kwargs)
  File "/home/airflow/.local/lib/python3.8/site-packages/airflow/models/taskinstance.py", line 734, in _execute_callable
    return ExecutionCallableRunner(
  File "/home/airflow/.local/lib/python3.8/site-packages/airflow/utils/operator_helpers.py", line 252, in run
    return self.func(*args, **kwargs)
  File "/home/airflow/.local/lib/python3.8/site-packages/airflow/models/baseoperator.py", line 424, in wrapper
    return func(self, *args, **kwargs)
  File "/home/airflow/.local/lib/python3.8/site-packages/airflow/operators/python.py", line 238, in execute
    return_value = self.execute_callable()
  File "/home/airflow/.local/lib/python3.8/site-packages/airflow/operators/python.py", line 256, in execute_callable
    return runner.run(*self.op_args, **self.op_kwargs)
  File "/home/airflow/.local/lib/python3.8/site-packages/airflow/utils/operator_helpers.py", line 252, in run
    return self.func(*args, **kwargs)
  File "/opt/airflow/dags/01_Bronce.py", line 371, in extract_and_load_table
    records_loaded = loader.load_data(df, bronze_table_name, if_exists='replace')
  File "/opt/airflow/dags/01_Bronce.py", line 288, in load_data
    self.create_table_if_not_exists(table_name, df_clean)
  File "/opt/airflow/dags/01_Bronce.py", line 230, in create_table_if_not_exists
    result = conn.execute(text(table_exists_query), (table_name,))
  File "/home/airflow/.local/lib/python3.8/site-packages/sqlalchemy/engine/base.py", line 1385, in execute
    return meth(self, multiparams, params, _EMPTY_EXECUTION_OPTS)
  File "/home/airflow/.local/lib/python3.8/site-packages/sqlalchemy/sql/elements.py", line 334, in _execute_on_connection
    return connection._execute_clauseelement(
  File "/home/airflow/.local/lib/python3.8/site-packages/sqlalchemy/engine/base.py", line 1577, in _execute_clauseelement
    ret = self._execute_context(
  File "/home/airflow/.local/lib/python3.8/site-packages/sqlalchemy/engine/base.py", line 1953, in _execute_context
    self._handle_dbapi_exception(
  File "/home/airflow/.local/lib/python3.8/site-packages/sqlalchemy/engine/base.py", line 2134, in _handle_dbapi_exception
    util.raise_(
  File "/home/airflow/.local/lib/python3.8/site-packages/sqlalchemy/util/compat.py", line 211, in raise_
    raise exception
  File "/home/airflow/.local/lib/python3.8/site-packages/sqlalchemy/engine/base.py", line 1910, in _execute_context
    self.dialect.do_execute(
  File "/home/airflow/.local/lib/python3.8/site-packages/sqlalchemy/engine/default.py", line 736, in do_execute
    cursor.execute(statement, parameters)
sqlalchemy.exc.ProgrammingError: (psycopg2.errors.SyntaxError) syntax error at or near "%"
LINE 4:                 WHERE table_name = %s
                                           ^

[SQL: 
            SELECT EXISTS (
                SELECT FROM information_schema.tables 
                WHERE table_name = %%s
            )
        ]
(Background on this error at: https://sqlalche.me/e/14/f405)
[2025-09-20T17:53:26.288+0000] {local_task_job_runner.py:266} INFO - Task exited with return code 1
[2025-09-20T17:53:26.393+0000] {taskinstance.py:3901} INFO - 0 downstream tasks scheduled from follow-on schedule check
[2025-09-20T17:53:26.398+0000] {local_task_job_runner.py:245} INFO - ::endgroup::
[2025-09-20T18:10:49.327+0000] {local_task_job_runner.py:123} INFO - ::group::Pre task execution logs
[2025-09-20T18:10:49.512+0000] {taskinstance.py:2614} INFO - Dependencies all met for dep_context=non-requeueable deps ti=<TaskInstance: bronze_full_load_spaceparts.extract_load_fact_Budget scheduled__2024-01-01T00:00:00+00:00 [queued]>
[2025-09-20T18:10:49.598+0000] {taskinstance.py:2614} INFO - Dependencies all met for dep_context=requeueable deps ti=<TaskInstance: bronze_full_load_spaceparts.extract_load_fact_Budget scheduled__2024-01-01T00:00:00+00:00 [queued]>
[2025-09-20T18:10:49.598+0000] {taskinstance.py:2867} INFO - Starting attempt 2 of 3
[2025-09-20T18:10:49.658+0000] {taskinstance.py:2890} INFO - Executing <Task(PythonOperator): extract_load_fact_Budget> on 2024-01-01 00:00:00+00:00
[2025-09-20T18:10:49.674+0000] {standard_task_runner.py:72} INFO - Started process 264 to run task
[2025-09-20T18:10:49.682+0000] {standard_task_runner.py:104} INFO - Running: ['***', 'tasks', 'run', 'bronze_full_load_spaceparts', 'extract_load_fact_Budget', 'scheduled__2024-01-01T00:00:00+00:00', '--job-id', '82', '--raw', '--subdir', 'DAGS_FOLDER/01_Bronce.py', '--cfg-path', '/tmp/tmp0bc01wi_']
[2025-09-20T18:10:49.694+0000] {standard_task_runner.py:105} INFO - Job 82: Subtask extract_load_fact_Budget
[2025-09-20T18:10:52.847+0000] {task_command.py:467} INFO - Running <TaskInstance: bronze_full_load_spaceparts.extract_load_fact_Budget scheduled__2024-01-01T00:00:00+00:00 [running]> on host dcfe59692ee1
[2025-09-20T18:10:53.243+0000] {taskinstance.py:3134} INFO - Exporting env vars: AIRFLOW_CTX_DAG_OWNER='data-team' AIRFLOW_CTX_DAG_ID='bronze_full_load_spaceparts' AIRFLOW_CTX_TASK_ID='extract_load_fact_Budget' AIRFLOW_CTX_EXECUTION_DATE='2024-01-01T00:00:00+00:00' AIRFLOW_CTX_TRY_NUMBER='2' AIRFLOW_CTX_DAG_RUN_ID='scheduled__2024-01-01T00:00:00+00:00'
[2025-09-20T18:10:53.246+0000] {taskinstance.py:732} INFO - ::endgroup::
[2025-09-20T18:10:53.286+0000] {01_Bronce.py:326} INFO - Starting extraction for table: fact.Budget
[2025-09-20T18:11:00.127+0000] {01_Bronce.py:338} INFO - Table fact.Budget has 2,947,811 rows
[2025-09-20T18:11:00.129+0000] {01_Bronce.py:352} INFO - Extracting data from fact.Budget
[2025-09-20T18:11:24.506+0000] {01_Bronce.py:369} INFO - Loading 2947811 rows to bronze_fact_budget
[2025-09-20T18:11:24.691+0000] {01_Bronce.py:269} ERROR - Error creating table bronze_fact_budget: (psycopg2.errors.DuplicateColumn) column "load_date" specified more than once

[SQL: 
            CREATE TABLE bronze_fact_budget (
                month BIGINT, total_budget DOUBLE PRECISION, customer_key TEXT, product_key BIGINT, dwcreateddate TIMESTAMP, load_date TIMESTAMP, source_system TEXT, load_date TIMESTAMP DEFAULT CURRENT_TIMESTAMP, source_system VARCHAR(50) DEFAULT 'spaceparts'
            )
        ]
(Background on this error at: https://sqlalche.me/e/14/f405)
[2025-09-20T18:11:24.691+0000] {01_Bronce.py:302} ERROR - Error loading data to bronze_fact_budget: (psycopg2.errors.DuplicateColumn) column "load_date" specified more than once

[SQL: 
            CREATE TABLE bronze_fact_budget (
                month BIGINT, total_budget DOUBLE PRECISION, customer_key TEXT, product_key BIGINT, dwcreateddate TIMESTAMP, load_date TIMESTAMP, source_system TEXT, load_date TIMESTAMP DEFAULT CURRENT_TIMESTAMP, source_system VARCHAR(50) DEFAULT 'spaceparts'
            )
        ]
(Background on this error at: https://sqlalche.me/e/14/f405)
[2025-09-20T18:11:24.691+0000] {01_Bronce.py:387} ERROR - Error processing table fact.Budget: (psycopg2.errors.DuplicateColumn) column "load_date" specified more than once

[SQL: 
            CREATE TABLE bronze_fact_budget (
                month BIGINT, total_budget DOUBLE PRECISION, customer_key TEXT, product_key BIGINT, dwcreateddate TIMESTAMP, load_date TIMESTAMP, source_system TEXT, load_date TIMESTAMP DEFAULT CURRENT_TIMESTAMP, source_system VARCHAR(50) DEFAULT 'spaceparts'
            )
        ]
(Background on this error at: https://sqlalche.me/e/14/f405)
[2025-09-20T18:11:24.705+0000] {taskinstance.py:3313} ERROR - Task failed with exception
Traceback (most recent call last):
  File "/home/airflow/.local/lib/python3.8/site-packages/sqlalchemy/engine/base.py", line 1910, in _execute_context
    self.dialect.do_execute(
  File "/home/airflow/.local/lib/python3.8/site-packages/sqlalchemy/engine/default.py", line 736, in do_execute
    cursor.execute(statement, parameters)
psycopg2.errors.DuplicateColumn: column "load_date" specified more than once


The above exception was the direct cause of the following exception:

Traceback (most recent call last):
  File "/home/airflow/.local/lib/python3.8/site-packages/airflow/models/taskinstance.py", line 768, in _execute_task
    result = _execute_callable(context=context, **execute_callable_kwargs)
  File "/home/airflow/.local/lib/python3.8/site-packages/airflow/models/taskinstance.py", line 734, in _execute_callable
    return ExecutionCallableRunner(
  File "/home/airflow/.local/lib/python3.8/site-packages/airflow/utils/operator_helpers.py", line 252, in run
    return self.func(*args, **kwargs)
  File "/home/airflow/.local/lib/python3.8/site-packages/airflow/models/baseoperator.py", line 424, in wrapper
    return func(self, *args, **kwargs)
  File "/home/airflow/.local/lib/python3.8/site-packages/airflow/operators/python.py", line 238, in execute
    return_value = self.execute_callable()
  File "/home/airflow/.local/lib/python3.8/site-packages/airflow/operators/python.py", line 256, in execute_callable
    return runner.run(*self.op_args, **self.op_kwargs)
  File "/home/airflow/.local/lib/python3.8/site-packages/airflow/utils/operator_helpers.py", line 252, in run
    return self.func(*args, **kwargs)
  File "/opt/airflow/dags/01_Bronce.py", line 370, in extract_and_load_table
    execution_summary = {
  File "/opt/airflow/dags/01_Bronce.py", line 287, in load_data
    logger.warning(f"Skipping empty table: {table_name}")
  File "/opt/airflow/dags/01_Bronce.py", line 265, in create_table_if_not_exists
    return tables
  File "/home/airflow/.local/lib/python3.8/site-packages/sqlalchemy/engine/base.py", line 1385, in execute
    return meth(self, multiparams, params, _EMPTY_EXECUTION_OPTS)
  File "/home/airflow/.local/lib/python3.8/site-packages/sqlalchemy/sql/elements.py", line 334, in _execute_on_connection
    return connection._execute_clauseelement(
  File "/home/airflow/.local/lib/python3.8/site-packages/sqlalchemy/engine/base.py", line 1577, in _execute_clauseelement
    ret = self._execute_context(
  File "/home/airflow/.local/lib/python3.8/site-packages/sqlalchemy/engine/base.py", line 1953, in _execute_context
    self._handle_dbapi_exception(
  File "/home/airflow/.local/lib/python3.8/site-packages/sqlalchemy/engine/base.py", line 2134, in _handle_dbapi_exception
    util.raise_(
  File "/home/airflow/.local/lib/python3.8/site-packages/sqlalchemy/util/compat.py", line 211, in raise_
    raise exception
  File "/home/airflow/.local/lib/python3.8/site-packages/sqlalchemy/engine/base.py", line 1910, in _execute_context
    self.dialect.do_execute(
  File "/home/airflow/.local/lib/python3.8/site-packages/sqlalchemy/engine/default.py", line 736, in do_execute
    cursor.execute(statement, parameters)
sqlalchemy.exc.ProgrammingError: (psycopg2.errors.DuplicateColumn) column "load_date" specified more than once

[SQL: 
            CREATE TABLE bronze_fact_budget (
                month BIGINT, total_budget DOUBLE PRECISION, customer_key TEXT, product_key BIGINT, dwcreateddate TIMESTAMP, load_date TIMESTAMP, source_system TEXT, load_date TIMESTAMP DEFAULT CURRENT_TIMESTAMP, source_system VARCHAR(50) DEFAULT 'spaceparts'
            )
        ]
(Background on this error at: https://sqlalche.me/e/14/f405)
[2025-09-20T18:11:24.718+0000] {taskinstance.py:1226} INFO - Marking task as UP_FOR_RETRY. dag_id=bronze_full_load_spaceparts, task_id=extract_load_fact_Budget, run_id=scheduled__2024-01-01T00:00:00+00:00, execution_date=20240101T000000, start_date=20250920T181049, end_date=20250920T181124
[2025-09-20T18:11:24.754+0000] {taskinstance.py:341} INFO - ::group::Post task execution logs
[2025-09-20T18:11:24.755+0000] {standard_task_runner.py:124} ERROR - Failed to execute job 82 for task extract_load_fact_Budget ((psycopg2.errors.DuplicateColumn) column "load_date" specified more than once

[SQL: 
            CREATE TABLE bronze_fact_budget (
                month BIGINT, total_budget DOUBLE PRECISION, customer_key TEXT, product_key BIGINT, dwcreateddate TIMESTAMP, load_date TIMESTAMP, source_system TEXT, load_date TIMESTAMP DEFAULT CURRENT_TIMESTAMP, source_system VARCHAR(50) DEFAULT 'spaceparts'
            )
        ]
(Background on this error at: https://sqlalche.me/e/14/f405); 264)
Traceback (most recent call last):
  File "/home/airflow/.local/lib/python3.8/site-packages/sqlalchemy/engine/base.py", line 1910, in _execute_context
    self.dialect.do_execute(
  File "/home/airflow/.local/lib/python3.8/site-packages/sqlalchemy/engine/default.py", line 736, in do_execute
    cursor.execute(statement, parameters)
psycopg2.errors.DuplicateColumn: column "load_date" specified more than once


The above exception was the direct cause of the following exception:

Traceback (most recent call last):
  File "/home/airflow/.local/lib/python3.8/site-packages/airflow/task/task_runner/standard_task_runner.py", line 117, in _start_by_fork
    ret = args.func(args, dag=self.dag)
  File "/home/airflow/.local/lib/python3.8/site-packages/airflow/cli/cli_config.py", line 49, in command
    return func(*args, **kwargs)
  File "/home/airflow/.local/lib/python3.8/site-packages/airflow/utils/cli.py", line 116, in wrapper
    return f(*args, **kwargs)
  File "/home/airflow/.local/lib/python3.8/site-packages/airflow/cli/commands/task_command.py", line 483, in task_run
    task_return_code = _run_task_by_selected_method(args, _dag, ti)
  File "/home/airflow/.local/lib/python3.8/site-packages/airflow/cli/commands/task_command.py", line 256, in _run_task_by_selected_method
    return _run_raw_task(args, ti)
  File "/home/airflow/.local/lib/python3.8/site-packages/airflow/cli/commands/task_command.py", line 341, in _run_raw_task
    return ti._run_raw_task(
  File "/home/airflow/.local/lib/python3.8/site-packages/airflow/utils/session.py", line 97, in wrapper
    return func(*args, session=session, **kwargs)
  File "/home/airflow/.local/lib/python3.8/site-packages/airflow/models/taskinstance.py", line 3006, in _run_raw_task
    return _run_raw_task(
  File "/home/airflow/.local/lib/python3.8/site-packages/airflow/models/taskinstance.py", line 274, in _run_raw_task
    TaskInstance._execute_task_with_callbacks(
  File "/home/airflow/.local/lib/python3.8/site-packages/airflow/models/taskinstance.py", line 3161, in _execute_task_with_callbacks
    result = self._execute_task(context, task_orig)
  File "/home/airflow/.local/lib/python3.8/site-packages/airflow/models/taskinstance.py", line 3185, in _execute_task
    return _execute_task(self, context, task_orig)
  File "/home/airflow/.local/lib/python3.8/site-packages/airflow/models/taskinstance.py", line 768, in _execute_task
    result = _execute_callable(context=context, **execute_callable_kwargs)
  File "/home/airflow/.local/lib/python3.8/site-packages/airflow/models/taskinstance.py", line 734, in _execute_callable
    return ExecutionCallableRunner(
  File "/home/airflow/.local/lib/python3.8/site-packages/airflow/utils/operator_helpers.py", line 252, in run
    return self.func(*args, **kwargs)
  File "/home/airflow/.local/lib/python3.8/site-packages/airflow/models/baseoperator.py", line 424, in wrapper
    return func(self, *args, **kwargs)
  File "/home/airflow/.local/lib/python3.8/site-packages/airflow/operators/python.py", line 238, in execute
    return_value = self.execute_callable()
  File "/home/airflow/.local/lib/python3.8/site-packages/airflow/operators/python.py", line 256, in execute_callable
    return runner.run(*self.op_args, **self.op_kwargs)
  File "/home/airflow/.local/lib/python3.8/site-packages/airflow/utils/operator_helpers.py", line 252, in run
    return self.func(*args, **kwargs)
  File "/opt/airflow/dags/01_Bronce.py", line 370, in extract_and_load_table
    execution_summary = {
  File "/opt/airflow/dags/01_Bronce.py", line 287, in load_data
    logger.warning(f"Skipping empty table: {table_name}")
  File "/opt/airflow/dags/01_Bronce.py", line 265, in create_table_if_not_exists
    return tables
  File "/home/airflow/.local/lib/python3.8/site-packages/sqlalchemy/engine/base.py", line 1385, in execute
    return meth(self, multiparams, params, _EMPTY_EXECUTION_OPTS)
  File "/home/airflow/.local/lib/python3.8/site-packages/sqlalchemy/sql/elements.py", line 334, in _execute_on_connection
    return connection._execute_clauseelement(
  File "/home/airflow/.local/lib/python3.8/site-packages/sqlalchemy/engine/base.py", line 1577, in _execute_clauseelement
    ret = self._execute_context(
  File "/home/airflow/.local/lib/python3.8/site-packages/sqlalchemy/engine/base.py", line 1953, in _execute_context
    self._handle_dbapi_exception(
  File "/home/airflow/.local/lib/python3.8/site-packages/sqlalchemy/engine/base.py", line 2134, in _handle_dbapi_exception
    util.raise_(
  File "/home/airflow/.local/lib/python3.8/site-packages/sqlalchemy/util/compat.py", line 211, in raise_
    raise exception
  File "/home/airflow/.local/lib/python3.8/site-packages/sqlalchemy/engine/base.py", line 1910, in _execute_context
    self.dialect.do_execute(
  File "/home/airflow/.local/lib/python3.8/site-packages/sqlalchemy/engine/default.py", line 736, in do_execute
    cursor.execute(statement, parameters)
sqlalchemy.exc.ProgrammingError: (psycopg2.errors.DuplicateColumn) column "load_date" specified more than once

[SQL: 
            CREATE TABLE bronze_fact_budget (
                month BIGINT, total_budget DOUBLE PRECISION, customer_key TEXT, product_key BIGINT, dwcreateddate TIMESTAMP, load_date TIMESTAMP, source_system TEXT, load_date TIMESTAMP DEFAULT CURRENT_TIMESTAMP, source_system VARCHAR(50) DEFAULT 'spaceparts'
            )
        ]
(Background on this error at: https://sqlalche.me/e/14/f405)
[2025-09-20T18:11:24.781+0000] {local_task_job_runner.py:266} INFO - Task exited with return code 1
[2025-09-20T18:11:24.831+0000] {taskinstance.py:3901} INFO - 0 downstream tasks scheduled from follow-on schedule check
[2025-09-20T18:11:24.834+0000] {local_task_job_runner.py:245} INFO - ::endgroup::
